Workbook

Sheet Company_Master
A1: 1 | B1: Index | C1: COMPANY CODE | D1: Company Name | E1: Mobile No | H1: License Expiry Date | I1: Est. Card Expiry | J1: Echannel Ex Date | K1: DAM- EXP | L1: Company Echannel User Name | M1: Echannel Password
A2: 2 | B2: brother Company | C2: C-001 | D2: DESERT WAVES CLEANING SERVICES - L.L.C - S.P.C | E2: 569383341 | H2: 27-07-2026 | I2: 46600 | J2: 22-09-2026 | K2: - | L2: Desertwaves_cleaning@outlook.com | M2: Desert@123
A3: 3 | C3: C-002 | D3: DESERT WAVES COMMERCIAL BROKERS - L.L.C - S.P.C | E3: 569383341 | H3: 46169 | I3: 46902 | J3: 46153 | K3: - | L3: desertwavesbrokers@gmail.com | M3: Desertbrokers@2017
A4: 4 | C4: C-003 | D4: JTS Cosmetic Trading | E4: 569383341 | H4: 0 | I4: 0 | J4: 0 | L4: 0 | M4: 0
A5: 5 | C5: C-004 | D5: Modern Minimalistic | E5: 569383341 | H5: 1 | I5: 1 | J5: 1 | L5: 0 | M5: 0
A6: 6 | C6: C-005 | D6: Pie beauty | E6: 569383341 | H6: 2 | I6: 2 | J6: 2 | L6: 0 | M6: 0
A7: 7 | C7: C-006 | D7: Easy Style Ladies | E7: 569383341 | H7: 3 | I7: 3 | J7: 3 | L7: 0 | M7: 0
A8: 8 | C8: C-007 | D8: Barakh event Management | E8: 569383341 | H8: 4 | I8: 4 | J8: 4 | L8: 0 | M8: 0
A9: 9 | B9: Data | C9: C-008 | D9: DATTA GENERAL TRADING AND LABORATORY SUPPLIES - L.L.C - S.P.C | E9: 588675581 | H9: 46365 | I9: 47017 | J9: 46283 | L9: dattageneral786@gmail.com | M9: Aa@123456
A10: 10 | C10: C-009 | D10: DATTA BUKHARI RESTAURANT - L.L.C - O.P.C | E10: 588675581 | H10: 46084 | I10: 46876 | J10: 46115 | L10: dattabukharirestaurant@gmail.com | M10: Datta@2024
A11: 11 | C11: C-010 | D11: DATTA HUJWIRI RESTAURANT - L.L.C - S.P.C | E11: 588675581 | H11: 47335 | I11: 46484 | J11: 46334 | L11: Dattagtls@gmail.com | M11: Nabeel@123456
A12: 12 | B12: Kattans | C12: C-011 | D12: ROYAL KATTANS KITCHEN - L.L.C | E12: 553256699 | H12: 46234 | I12: 46921 | J12: 46171 | L12: auhkattans@gmail.com | M12: Aa@123456
A13: 13 | C13: C-012 | D13: ROYAL KATTAN KITCHEN -L.L.C BRANCH | E13: 553256699 | H13: 46453 | I13: 46941 | J13: 46365 | L13: SABKHACAFETERIAAUHBR3@GMAIL.COM | M13: Sabkha@2024
A14: 14 | C14: C-013 | D14: KATTANS CAFÉ L.L.C | E14: 553256699 | H14: 46210 | I14: 46340 | J14: 46510 | L14: nafinchalil72@gmail.com | M14: Tastytreat@2021
A15: 15 | C15: C-014 | D15: KATTANS CAFE L.L.C. - BRANCH | E15: 553256699 | H15: 46085 | I15: 28/03/2027 | J15: 15/01/2027 | L15: kattanscafellcbr1@gmail.com | M15: Kattans@23
A16: 16 | C16: C-015 | D16: Estorie Mobile Phone | E16: 553256699 | H16: 19/09/2028 | I16: 18-09-2027 | J16: 46285 | L16: estorie2023auh@gmail.com | M16: Aa@123456
A17: 17 | C17: C-016 | D17: Froied Chicken | E17: 553256699 | H17: 0 | I17: 0 | J17: 0 | L17: 0 | M17: 0
A18: 18 | B18: Way to Way | C18: C-017 | D18: WAY 2 WAY PASSENGER TRANSPORT BY RENTED BUSES - L.L.C - S.P.C | E18: 529910008 | H18: 46999 | I18: 47033 | J18: 46120 | L18: Way2waytransport2@gmail.com | M18: Aa@123456
A19: 19 | C19: C-018 | D19: WAY 2 WAY TOURS AND SAFARI - L.L.C - S.P.C | E19: 529910008 | H19: 46274 | I19: 46249 | J19: 46374 | L19: waywaypassanger@gmail.com | M19: Aa@123456
A20: 20 | C20: C-019 | D20: EURO ARAB TOURISM - L.L.C - O.P.C | E20: 552914478 | H20: 46392 | I20: 46124 | J20: 46218 | L20: euroarabtourism@gmail.com | M20: Aa@123456
A21: 21 | C21: C-020 | D21: WADI RENTAL EQUIPMENT CONSTRUCTION - L.L.C - S.P.C | E21: 565620211 | H21: 46084 | I21: 46348 | J21: 46107 | L21: wadirentalequipmentconstructio@gmail.com | M21: Wadi@2024
A22: 22 | C22: C-021 | D22: NEELAS LADIES BEAUTY SALOON - L.L.C - O.P.C | E22: 525863107 | H22: 46149 | I22: 46781 | J22: 46693 | L22: neelasbeautysalon@gmail.com | M22: Aa@123456
A23: 23 | C23: C-022 | D23: LE SIGNATURE MEATS - SOLE PROPRIETORSHIP L.L.C. | E23: 529425234 | H23: 09/05/2026 | I23: 46522 | J23: 46227 | L23: lesignature69@gmail.com | M23: Lesign@2024
A24: 24 | C24: C-023 | D24: AKCELLENCE TRANSPORT PASSENGER BY BUS - L.L.C | E24: 504430298 | H24: 16/07/2026 | I24: 47095 | J24: 46225 | L24: akcellencetransportcompany@gmail.com | M24: Aa@123456
A25: 25 | C25: C-024 | D25: TECHNO MART TRADING - SOLE PROPRIETORSHIP L.L.C. | E25: 504554979 | H25: 15/05/2026 | I25: 46772 | J25: 46392 | L25: tmtptllc@gmail.com | M25: Pipes@12
A26: 26 | C26: C-025 | D26: Haflas Baqala | E26: 504554979
A27: 27 | C27: C-026 | D27: Dazzling Mobile Car Wash | E27: 564893948
A28: 28 | C28: C-027 | D28: TOP SEA FRESH FISH - L.L.C | E28: 508503154 | H28: 15/08/2027 | I28: 47055 | J28: 46241 | L28: topseafreshfish@gmail.com | M28: Topsea123
A29: 29 | C29: C-028 | D29: TOPSEA ELECTROMECHANICAL WORKS AND MAINTENANCE - L.L.C | E29: 508503154 | H29: 46362 | I29: 46362 | J29: 46186 | L29: topsea.electromechanichal@gmail.com | M29: Aa@123456
A30: 30 | C30: C-029 | D30: T M GENERAL MAINTENANCE & PROPERTY - L.L.C - S.P.C | E30: 586444975 | H30: 19/07/2027 | I30: 46227 | J30: 46163 | L30: tmpropertiesmanagement@gmail.com | M30: Aa@123456
A31: 31 | C31: C-030 | D31: ILAMA FOODSTUFF TRADING - L.L.C - S.P.C | E31: 561536153 | H31: 46413 | I31: 47146 | J31: 46414
A32: 32 | C32: C-031 | D32: Al zawaya | E32: 566114212
A33: 33 | C33: C-032 | D33: FASTE AVENUE TRANSPORT - S.P.C-L.L.C | E33: 558303070 | H33: 46175 | I33: 46181 | J33: 46242
A34: 34 | C34: C-033 | D34: Fast Transport Dubai | E34: 558303070
A35: 35 | C35: C-034 | D35: AL NAJOUM EGG TRADING | E35: 509755044
A36: 36 | C36: C-035 | D36: XOFOZ INFORMATION TECHNOLOGY -L.L.C. SPC | E36: 554969832
A37: 37 | C37: C-036 | D37: Golden Falcon | E37: 501796869
A38: 38 | C38: C-037 | D38: SKILLSAFE TRAINING AND INSPECTION SERVICES -L.L.C - O.PC | E38: 508202367
A39: 39 | C39: C-038 | D39: DATA BOOKKEEPING AND ACCOUNTING SERVICES | E39: 504152759
A40: 40 | C40: C-039 | D40: Yemen saloon | E40: 502566613
...

Sheet Employee_Master
A1: Sl No | B1: COMPANY NO | C1: COMPANY NAME | D1: Emirates ID | E1: Name | F1: LC CARD NO | G1: Labour Expiry Date | H1: ID expiry Date | I1: Daman Expiry Date | J1: Column1 | K1: Column2
A2: 1 | B2: =Company_Master!C2 -> C-001 | C2: =INDEX(Com_Scr!C:C,MATCH(Employee_Master!B:B,Com_Scr!B:B)) -> DESERT WAVES CLEANING SERVICES - L.L.C - S.P.C | D2: 784196504047612 | E2: MARIA THERESA DE LUNA LEDESMA | F2: 136762071 | G2: 46838 | H2: 46817 | I2: Company
A3: 2 | B3: =Company_Master!C2 -> C-001 | C3: =INDEX(Com_Scr!C:C,MATCH(Employee_Master!B:B,Com_Scr!B:B)) -> DESERT WAVES CLEANING SERVICES - L.L.C - S.P.C | D3: 784197808517540 | E3: MARY ANN LORETO CATIBOG | F3: 137448310 | G3: 46834 | H3: 46836 | I3: Company
A4: 3 | B4: =Company_Master!C2 -> C-001 | C4: =INDEX(Com_Scr!C:C,MATCH(Employee_Master!B:B,Com_Scr!B:B)) -> DESERT WAVES CLEANING SERVICES - L.L.C - S.P.C | D4: 784197079326860 | E4: ALICIA VIKKAMOR ALEGRE | F4: 135286381 | G4: 46765 | H4: 46769 | I4: Company
A5: 4 | B5: C-001 | C5: =INDEX(Com_Scr!C:C,MATCH(Employee_Master!B:B,Com_Scr!B:B)) -> DESERT WAVES CLEANING SERVICES - L.L.C - S.P.C | D5: 784197153038258 | E5: IRENE MONDOZA ANARCON | F5: 131163975 | G5: 46670 | H5: 46653 | I5: Company
A6: 5 | B6: C-001 | C6: =INDEX(Com_Scr!C:C,MATCH(Employee_Master!B:B,Com_Scr!B:B)) -> DESERT WAVES CLEANING SERVICES - L.L.C - S.P.C | D6: 784199076043175 | E6: MICAH LARISMA MAGPANTAY | F6: 136711384 | G6: 46817 | H6: 46814 | I6: Company
A7: 6 | B7: C-001 | C7: =INDEX(Com_Scr!C:C,MATCH(Employee_Master!B:B,Com_Scr!B:B)) -> DESERT WAVES CLEANING SERVICES - L.L.C - S.P.C | D7: 784197409092570 | E7: DZHAMILIA KURTANOVA | F7: 132793948 | G7: 46698 | H7: 46702 | I7: Company
A8: 7 | B8: C-001 | C8: =INDEX(Com_Scr!C:C,MATCH(Employee_Master!B:B,Com_Scr!B:B)) -> DESERT WAVES CLEANING SERVICES - L.L.C - S.P.C | D8: 784197061647547 | E8: MACARIA BAHIA DELOS REYES | F8: 132793948 | G8: 47064 | H8: 46665 | I8: Company
A9: 8 | B9: C-001 | C9: =INDEX(Com_Scr!C:C,MATCH(Employee_Master!B:B,Com_Scr!B:B)) -> DESERT WAVES CLEANING SERVICES - L.L.C - S.P.C | D9: 784198739682858 | E9: MIGUEL RICARDO BANTIGUE SUAREZ | F9: 139214754 | G9: 46634 | H9: 46598 | I9: Company
A10: 9 | B10: C-001 | C10: =INDEX(Com_Scr!C:C,MATCH(Employee_Master!B:B,Com_Scr!B:B)) -> DESERT WAVES CLEANING SERVICES - L.L.C - S.P.C | D10: 784198995296179 | E10: RECHELLE VINUYA ESPENIDA | F10: 114255725 | G10: 46129 | H10: 46150 | I10: Company
A11: 10 | B11: C-001 | C11: =INDEX(Com_Scr!C:C,MATCH(Employee_Master!B:B,Com_Scr!B:B)) -> DESERT WAVES CLEANING SERVICES - L.L.C - S.P.C | D11: 784197770206437 | E11: ANNA ROCHELLE BAUTISTA FILLE | F11: 131263621 | G11: 46670 | H11: 46658 | I11: Company
A12: 11 | B12: C-001 | C12: =INDEX(Com_Scr!C:C,MATCH(Employee_Master!B:B,Com_Scr!B:B)) -> DESERT WAVES CLEANING SERVICES - L.L.C - S.P.C | D12: 784198913696302 | E12: ERNIELITO ESPERANZA ALAGER | F12: 115100002 | G12: 46139 | H12: 46151 | I12: Company
A13: 12 | B13: C-001 | C13: =INDEX(Com_Scr!C:C,MATCH(Employee_Master!B:B,Com_Scr!B:B)) -> DESERT WAVES CLEANING SERVICES - L.L.C - S.P.C | D13: 784196974146092 | E13: IRMA MACALLA LOZADA | F13: 133237182 | G13: 46713 | H13: 46716 | I13: Company
A14: 13 | B14: C-001 | C14: =INDEX(Com_Scr!C:C,MATCH(Employee_Master!B:B,Com_Scr!B:B)) -> DESERT WAVES CLEANING SERVICES - L.L.C - S.P.C | D14: 784199092483843 | E14: NOORMOHAMMED OTTITI HAMSA HAMSA OTTIRI | F14: 118623204 | G14: 46303 | H14: 46305 | I14: Company
A15: 14 | B15: C-001 | C15: =INDEX(Com_Scr!C:C,MATCH(Employee_Master!B:B,Com_Scr!B:B)) -> DESERT WAVES CLEANING SERVICES - L.L.C - S.P.C | D15: 784198659209609 | E15: KAREN TEJADA JORLUCAS | F15: 136182939 | G15: 46796 | H15: 46796 | I15: Company
A16: 15 | B16: C-001 | C16: =INDEX(Com_Scr!C:C,MATCH(Employee_Master!B:B,Com_Scr!B:B)) -> DESERT WAVES CLEANING SERVICES - L.L.C - S.P.C | D16: 784198665153833 | E16: MARY GRACE DE JESUS RAMIREZ | F16: 118433175 | G16: 46296 | H16: 46183 | I16: Company
... A20: 19 | B20: C-001 | C20: =INDEX(Com_Scr!C:C,MATCH(Employee_Master!B:B,Com_Scr!B:B)) -> DESERT WAVES CLEANING SERVICES - L.L.C - S.P.C | D20: 784198691894301 | E20: MADINA RUZIMURATOVNA SHAPULATOVA | F20: 136500210 | G20: 46817 | H20: 46806 | I20: Company
A21: 20 | B21: C-002 | C21: =INDEX(Com_Scr!C:C,MATCH(Employee_Master!B:B,Com_Scr!B:B)) -> DESERT WAVES COMMERCIAL BROKERS - L.L.C - S.P.C | D21: 784198061083063 | E21: MARLON GUINTO GAPAY | F21: 121770458 | G21: 46389 | H21: 46772
A22: 21 | B22: C-002 | C22: =INDEX(Com_Scr!C:C,MATCH(Employee_Master!B:B,Com_Scr!B:B)) -> DESERT WAVES COMMERCIAL BROKERS - L.L.C - S.P.C | D22: 784197796391494 | E22: JENEVIE OFRANCIA MECADO | F22: 120930393 | G22: 46376 | H22: 46378
A23: 22 | B23: C-002 | C23: =INDEX(Com_Scr!C:C,MATCH(Employee_Master!B:B,Com_Scr!B:B)) -> DESERT WAVES COMMERCIAL BROKERS - L.L.C - S.P.C | D23: 784199448620965 | E23: SANTHOSHI RANA MAGAR | F23: 129643861 | G23: 46611 | H23: 46620
A24: 23 | B24: C-002 | C24: =INDEX(Com_Scr!C:C,MATCH(Employee_Master!B:B,Com_Scr!B:B)) -> DESERT WAVES COMMERCIAL BROKERS - L.L.C - S.P.C | D24: 784199346478896 | E24: ESAM ALY ABDUL | F24: 135808704 | G24: 46779 | H24: 46782
A25: 24 | B25: C-002 | C25: =INDEX(Com_Scr!C:C,MATCH(Employee_Master!B:B,Com_Scr!B:B)) -> DESERT WAVES COMMERCIAL BROKERS - L.L.C - S.P.C | D25: 784198892621537 | E25: JOVANE LABON ESPINO | F25: 135173825 | G25: 46745 | H25: 46760
A26: 25 | B26: C-002 | C26: =INDEX(Com_Scr!C:C,MATCH(Employee_Master!B:B,Com_Scr!B:B)) -> DESERT WAVES COMMERCIAL BROKERS - L.L.C - S.P.C | D26: 784199434455897 | E26: ANAS EYAD AHMAD NAZZAL | F26: 120780226 | G26: 46380 | H26: 46371
A27: 26 | B27: C-002 | C27: =INDEX(Com_Scr!C:C,MATCH(Employee_Master!B:B,Com_Scr!B:B)) -> DESERT WAVES COMMERCIAL BROKERS - L.L.C - S.P.C | D27: 784198460978426 | E27: DENNIS GLORIOSO LORENZO | F27: 121770458 | G27: 46389 | H27: 46399
A28: 27 | B28: C-002 | C28: =INDEX(Com_Scr!C:C,MATCH(Employee_Master!B:B,Com_Scr!B:B)) -> DESERT WAVES COMMERCIAL BROKERS - L.L.C - S.P.C | D28: 784198814707018 | E28: MARISSA PALISOC GOLETA | F28: 114289767 | G28: 46151 | H28: 46154
A29: 28 | B29: C-002 | C29: =INDEX(Com_Scr!C:C,MATCH(Employee_Master!B:B,Com_Scr!B:B)) -> DESERT WAVES COMMERCIAL BROKERS - L.L.C - S.P.C | D29: 784198470959499 | E29: RANDELL ESPENILLA BALGOS | F29: 123204860 | G29: 46426 | H29: 46432
A30: 29 | B30: C-002 | C30: =INDEX(Com_Scr!C:C,MATCH(Employee_Master!B:B,Com_Scr!B:B)) -> DESERT WAVES COMMERCIAL BROKERS - L.L.C - S.P.C | D30: 784198524203217 | E30: DANNA ROGEL CONDE | F30: 134711840 | G30: 46698 | H30: 46746
A31: 30 | B31: C-002 | C31: =INDEX(Com_Scr!C:C,MATCH(Employee_Master!B:B,Com_Scr!B:B)) -> DESERT WAVES COMMERCIAL BROKERS - L.L.C - S.P.C | D31: 784198616042069 | E31: AGNES QUIN SARGADO | F31: 134521243 | G31: 46726 | H31: 46752
A32: 31 | B32: C-002 | C32: =INDEX(Com_Scr!C:C,MATCH(Employee_Master!B:B,Com_Scr!B:B)) -> DESERT WAVES COMMERCIAL BROKERS - L.L.C - S.P.C | D32: 784198470350285 | E32: RACHEL BENEDICTO CRUZ | F32: 133573686 | G32: 46732 | H32: 46726
... A43: 42 | B43: C-002 | C43: =INDEX(Com_Scr!C:C,MATCH(Employee_Master!B:B,Com_Scr!B:B)) -> DESERT WAVES COMMERCIAL BROKERS - L.L.C - S.P.C | D43: 784198065991162 | E43: ROEL REYES EVANGELISTA | F43: 117182857 | G43: 46247 | H43: 46259
A44: 43 | B44: C-008 | C44: =INDEX(Com_Scr!C:C,MATCH(Employee_Master!B:B,Com_Scr!B:B)) -> DATTA GENERAL TRADING AND LABORATORY SUPPLIES - L.L.C - S.P.C | D44: 784200123136606 | E44: JUSTIN CANTA ESCALA | F44: 131990426 | G44: 46657 | H44: 46772 | J44: PART TIME
A45: 44 | B45: C-008 | C45: =INDEX(Com_Scr!C:C,MATCH(Employee_Master!B:B,Com_Scr!B:B)) -> DATTA GENERAL TRADING AND LABORATORY SUPPLIES - L.L.C - S.P.C | D45: 784199764523116 | E45: MARK ANTHONY ARANDELA ACOSTA | F45: 131990416 | G45: 46815 | H45: 46378
A46: 45 | B46: C-008 | C46: =INDEX(Com_Scr!C:C,MATCH(Employee_Master!B:B,Com_Scr!B:B)) -> DATTA GENERAL TRADING AND LABORATORY SUPPLIES - L.L.C - S.P.C | D46: 784197661594768 | E46: GINHAWA TALPLACIDO ACOSTA | F46: 137524570 | G46: 46657 | H46: 46620
A47: 46 | B47: C-008 | C47: =INDEX(Com_Scr!C:C,MATCH(Employee_Master!B:B,Com_Scr!B:B)) -> DATTA GENERAL TRADING AND LABORATORY SUPPLIES - L.L.C - S.P.C | D47: 784198735750279 | E47: AQEEL AHMED MUHAMMAD SIDDIQUE | F47: 116359557 | G47: 46225 | H47: GOLDEN
A48: 47 | B48: C-009 | C48: =INDEX(Com_Scr!C:C,MATCH(Employee_Master!B:B,Com_Scr!B:B)) -> DATTA BUKHARI RESTAURANT - L.L.C - O.P.C | D48: 784198241913080 | E48: ERMAWATI BT CUCU SURYADI BASON | F48: 118673455 | G48: 46304 | H48: 46327
A49: 48 | B49: C-009 | C49: =INDEX(Com_Scr!C:C,MATCH(Employee_Master!B:B,Com_Scr!B:B)) -> DATTA BUKHARI RESTAURANT - L.L.C - O.P.C | D49: 784200060808274 | E49: DANISH IDREES MUHAMMAD IDREES QAZI | F49: 126935911 | G49: 46539 | H49: 46584
A50: 49 | B50: C-009 | C50: =INDEX(Com_Scr!C:C,MATCH(Employee_Master!B:B,Com_Scr!B:B)) -> DATTA BUKHARI RESTAURANT - L.L.C - O.P.C | D50: 784198784614053 | E50: ARIANE VILLAFLOR OCO | F50: 130639640 | G50: 46639 | H50: 46652
A51: 50 | B51: C-009 | C51: =INDEX(Com_Scr!C:C,MATCH(Employee_Master!B:B,Com_Scr!B:B)) -> DATTA BUKHARI RESTAURANT - L.L.C - O.P.C | D51: 784198580960239 | E51: NISAR HABIB MUHAMMAD SIDDIQUE ANJUM | F51: 117903164 | G51: 46280 | H51: 46288
A52: 51 | B52: C-009 | C52: =INDEX(Com_Scr!C:C,MATCH(Employee_Master!B:B,Com_Scr!B:B)) -> DATTA BUKHARI RESTAURANT - L.L.C - O.P.C | D52: 784199328580313 | E52: MAHMOUD ABDELNASER AHMED MOUSTAFA | F52: 119834812 | G52: 46337 | H52: 46343
A53: 52 | B53: C-009 | C53: =INDEX(Com_Scr!C:C,MATCH(Employee_Master!B:B,Com_Scr!B:B)) -> DATTA BUKHARI RESTAURANT - L.L.C - O.P.C | D53: 784200159632866 | E53: RAJU B K | F53: 115047636 | G53: 46178 | H53: 46180
...

Sheet Com_Scr
A1: Sl.No | B1: Company Code | C1: Company Name | D1: INDEX | E1: No of Employees
A2: 1 | B2: C-001 | C2: =INDEX(Company_Master!D:D,MATCH(B2,Company_Master!C:C,0)) -> DESERT WAVES CLEANING SERVICES - L.L.C - S.P.C | D2: DES WAV CLEANING | E2: =COUNTIF(Employee_Master!B:B,Com_Scr!B2) -> 19
A3: 2 | B3: C-002 | C3: =INDEX(Company_Master!D:D,MATCH(B3,Company_Master!C:C,0)) -> DESERT WAVES COMMERCIAL BROKERS - L.L.C - S.P.C | D3: DES WAV BROKER | E3: =COUNTIF(Employee_Master!B:B,Com_Scr!B3) -> 23
A4: 3 | B4: C-008 | C4: =INDEX(Company_Master!D:D,MATCH(B4,Company_Master!C:C,0)) -> DATTA GENERAL TRADING AND LABORATORY SUPPLIES - L.L.C - S.P.C | D4: DATTA TRADING | E4: =COUNTIF(Employee_Master!B:B,Com_Scr!B4) -> 4
A5: 4 | B5: C-009 | C5: =INDEX(Company_Master!D:D,MATCH(B5,Company_Master!C:C,0)) -> DATTA BUKHARI RESTAURANT - L.L.C - O.P.C | D5: DATTA BUKHARI | E5: =COUNTIF(Employee_Master!B:B,Com_Scr!B5) -> 7
A6: 39 | B6: C-010 | C6: =INDEX(Company_Master!D:D,MATCH(B6,Company_Master!C:C,0)) -> DATTA HUJWIRI RESTAURANT - L.L.C - S.P.C | E6: =COUNTIF(Employee_Master!B:B,Com_Scr!B6) -> 5
A7: 5 | B7: C-011 | C7: =INDEX(Company_Master!D:D,MATCH(B7,Company_Master!C:C,0)) -> ROYAL KATTANS KITCHEN - L.L.C | D7: DATTA | E7: =COUNTIF(Employee_Master!B:B,Com_Scr!B7) -> 13
A8: 6 | B8: C-012 | C8: =INDEX(Company_Master!D:D,MATCH(B8,Company_Master!C:C,0)) -> ROYAL KATTAN KITCHEN -L.L.C BRANCH | E8: =COUNTIF(Employee_Master!B:B,Com_Scr!B8) -> 7
A9: 7 | B9: C-013 | C9: =INDEX(Company_Master!D:D,MATCH(B9,Company_Master!C:C,0)) -> KATTANS CAFÉ L.L.C | E9: =COUNTIF(Employee_Master!B:B,Com_Scr!B9) -> 23
A10: 8 | B10: C-014 | C10: =INDEX(Company_Master!D:D,MATCH(B10,Company_Master!C:C,0)) -> KATTANS CAFE L.L.C. - BRANCH | E10: =COUNTIF(Employee_Master!B:B,Com_Scr!B10) -> 17
A11: 9 | B11: C-017 | C11: =INDEX(Company_Master!D:D,MATCH(B11,Company_Master!C:C,0)) -> WAY 2 WAY PASSENGER TRANSPORT BY RENTED BUSES - L.L.C - S.P.C | E11: =COUNTIF(Employee_Master!B:B,Com_Scr!B11) -> 18
A12: 10 | B12: C-018 | C12: =INDEX(Company_Master!D:D,MATCH(B12,Company_Master!C:C,0)) -> WAY 2 WAY TOURS AND SAFARI - L.L.C - S.P.C | E12: =COUNTIF(Employee_Master!B:B,Com_Scr!B12) -> 8
A13: 11 | B13: C-019 | C13: =INDEX(Company_Master!D:D,MATCH(B13,Company_Master!C:C,0)) -> EURO ARAB TOURISM - L.L.C - O.P.C | E13: =COUNTIF(Employee_Master!B:B,Com_Scr!B13) -> 15
A14: 12 | B14: C-020 | C14: =INDEX(Company_Master!D:D,MATCH(B14,Company_Master!C:C,0)) -> WADI RENTAL EQUIPMENT CONSTRUCTION - L.L.C - S.P.C | E14: =COUNTIF(Employee_Master!B:B,Com_Scr!B14) -> 7
A15: 13 | B15: C-021 | C15: =INDEX(Company_Master!D:D,MATCH(B15,Company_Master!C:C,0)) -> NEELAS LADIES BEAUTY SALOON - L.L.C - O.P.C | E15: =COUNTIF(Employee_Master!B:B,Com_Scr!B15) -> 4
A16: 14 | B16: C-022 | C16: =INDEX(Company_Master!D:D,MATCH(B16,Company_Master!C:C,0)) -> LE SIGNATURE MEATS - SOLE PROPRIETORSHIP L.L.C. | E16: =COUNTIF(Employee_Master!B:B,Com_Scr!B16) -> 2
A17: 15 | B17: C-023 | C17: =INDEX(Company_Master!D:D,MATCH(B17,Company_Master!C:C,0)) -> AKCELLENCE TRANSPORT PASSENGER BY BUS - L.L.C | E17: =COUNTIF(Employee_Master!B:B,Com_Scr!B17) -> 6
A18: 16 | B18: C-027 | C18: =INDEX(Company_Master!D:D,MATCH(B18,Company_Master!C:C,0)) -> TOP SEA FRESH FISH - L.L.C | E18: =COUNTIF(Employee_Master!B:B,Com_Scr!B18) -> 4
A19: 17 | B19: C-029 | C19: =INDEX(Company_Master!D:D,MATCH(B19,Company_Master!C:C,0)) -> T M GENERAL MAINTENANCE & PROPERTY - L.L.C - S.P.C | E19: =COUNTIF(Employee_Master!B:B,Com_Scr!B19) -> 5
... A42: 38 | B42: C-253 | C42: =INDEX(Company_Master!D:D,MATCH(B42,Company_Master!C:C,0)) -> SABIR C-O | E42: =COUNTIF(Employee_Master!B:B,Com_Scr!B42) -> 0
B44: 0
E45: =SUM(E2:E42) -> 380

Sheet Marketing List
A1: NOOR AL HUDA TYPING & PHOTOCOPYING SERVICES
A2: SL.No | B2: Company Name | C2: Representitive Name | D2: Contact No
A3: 1 | B3: Al Bakht Curtain | C3: Shaad | D3: 523202606
